Failure # 1 (occurred at 2022-12-25_10-33-13)
[36mray::ImplicitFunc.train()[39m (pid=22402, ip=10.0.0.11, repr=train)
  File "/home/azureuser/.cache/pypoetry/virtualenvs/ml22-hypertune-Thr_2dul-py3.9/lib/python3.9/site-packages/ray/tune/trainable/trainable.py", line 367, in train
    raise skipped from exception_cause(skipped)
  File "/home/azureuser/.cache/pypoetry/virtualenvs/ml22-hypertune-Thr_2dul-py3.9/lib/python3.9/site-packages/ray/tune/trainable/function_trainable.py", line 335, in entrypoint
    return self._trainable_func(
  File "/home/azureuser/.cache/pypoetry/virtualenvs/ml22-hypertune-Thr_2dul-py3.9/lib/python3.9/site-packages/ray/tune/trainable/function_trainable.py", line 652, in _trainable_func
    output = fn()
  File "/home/azureuser/ML22/ML22-hypertune/hypertune.py", line 33, in train
    trainloader, testloader = make_dataset.get_imdb_data(data_dir=data_dir)
TypeError: get_imdb_data() got an unexpected keyword argument 'data_dir'
